Workbook

Sheet Executive Dashboard
B2: OIL_GAS_MINING INC — NATURAL RESOURCES, OIL, GAS & MINING EXECUTIVE DASHBOARD
B3: Interactive Energy & Heavy Extraction BI Model • Dynamic Live Formulas & Visual Analytics • Generated: 2026-10-23 • Status: Final Verified
B4: Basin / Concession Area: | C4: All Basins | F4: Channel: | G4: All Channels | J4: 💡 Tip: Select dropdown in C4 (Basin / Concession Area) or G4 (Channel) in Excel to recalculate entire dashboard dynamically!
B6: TOTAL UPSTREAM PRODUCTION REVENUE | D6: NET CRACK SPREAD & REFINING MARGIN | F6: EXTRACTION SAFETY ADHERENCE % | H6: ACTIVE RIG FIELDS / MINERAL LEASES | J6: TOTAL BARRELS / TONS PRODUCED | L6: AVG PRODUCTION COST PER BARREL | N6: ACTIVE CUSTOMERS
B7: =IF(AND(C4="All Basins", G4="All Channels"), SUM('Sales Transactions'!T3:T82), IF(C4="All Basins", SUMIFS('Sales Transactions'!T3:T82, 'Sales Transactions'!L3:L82, G4), IF(G4="All Channels", SUMIFS('Sales Transactions'!T3:T82, 'Sales Transactions'!H3:H82, C4), SUMIFS('Sales Transactions'!T3:T82, 'Sales Transactions'!H3:H82, C4, 'Sales Transactions'!L3:L82, G4)))) -> 3769345 | D7: =IF(AND(C4="All Basins", G4="All Channels"), SUM('Sales Transactions'!V3:V82), IF(C4="All Basins", SUMIFS('Sales Transactions'!V3:V82, 'Sales Transactions'!L3:L82, G4), IF(G4="All Channels", SUMIFS('Sales Transactions'!V3:V82, 'Sales Transactions'!H3:H82, C4), SUMIFS('Sales Transactions'!V3:V82, 'Sales Transactions'!H3:H82, C4, 'Sales Transactions'!L3:L82, G4)))) -> 2392445 | F7: =IF(B7>0, D7/B7, "N/A") -> 0.6347 | H7: =IF(AND(C4="All Basins", G4="All Channels"), SUM('Sales Transactions'!R3:R82), IF(C4="All Basins", SUMIFS('Sales Transactions'!R3:R82, 'Sales Transactions'!L3:L82, G4), IF(G4="All Channels", SUMIFS('Sales Transactions'!R3:R82, 'Sales Transactions'!H3:H82, C4), SUMIFS('Sales Transactions'!R3:R82, 'Sales Transactions'!H3:H82, C4, 'Sales Transactions'!L3:L82, G4)))) -> 254 | J7: =IF(AND(C4="All Basins", G4="All Channels"), COUNTA('Sales Transactions'!A3:A82), IF(C4="All Basins", COUNTIFS('Sales Transactions'!L3:L82, G4), IF(G4="All Channels", COUNTIFS('Sales Transactions'!H3:H82, C4), COUNTIFS('Sales Transactions'!H3:H82, C4, 'Sales Transactions'!L3:L82, G4)))) -> 80 | L7: =IF(J7>0, B7/J7, 0) -> 47116.81 | N7: 6
B8: ● Net Ledger Revenue | D8: ● Operating Profit | F8: ● Margin Ratio | H8: ● Total Units | J8: ● Total Transactions | L8: ● Avg Ticket / Deal | N8: ● Distinct Accounts
B44: MONTHLY TOTAL UPSTREAM PRODUCTION REVENUE & NET CRACK SPREAD & REFINING MARGIN RUN-RATE SUMMARY | I44: BASIN / CONCESSION AREA PERFORMANCE SCORECARD
B45: Period | C45: Upstream Production Revenue ($) | D45: Direct Cost ($) | E45: Net Crack Spread & Refining Margin ($) | F45: Extraction Safety Adherence % | G45: Volume | H45: In-Cell Trend | I45: Basin / Concession Area | J45: Orders | K45: Actual Upstream Production Revenue | L45: Total COGS | M45: Gross Margin % | N45: Net Crack Spread & Refining Margin | O45: Profitability
B46: Jan '24 | C46: =IF(AND($C$4="All Basins", $G$4="All Channels"), SUMIFS('Sales Transactions'!$T$3:$T$82, 'Sales Transactions'!$B$3:$B$82, "2024-01*"), IF($C$4="All Basins", SUMIFS('Sales Transactions'!$T$3:$T$82, 'Sales Transactions'!$B$3:$B$82, "2024-01*", 'Sales Transactions'!$L$3:$L$82, $G$4), IF($G$4="All Channels", SUMIFS('Sales Transactions'!$T$3:$T$82, 'Sales Transactions'!$B$3:$B$82, "2024-01*", 'Sales Transactions'!$H$3:$H$82, $C$4), SUMIFS('Sales Transactions'!$T$3:$T$82, 'Sales Transactions'!$B$3:$B$82, "2024-01*", 'Sales Transactions'!$H$3:$H$82, $C$4, 'Sales Transactions'!$L$3:$L$82, $G$4)))) -> 70670 | D46: =C46-E46 -> 24200 | E46: =IF(AND($C$4="All Basins", $G$4="All Channels"), SUMIFS('Sales Transactions'!$V$3:$V$82, 'Sales Transactions'!$B$3:$B$82, "2024-01*"), IF($C$4="All Basins", SUMIFS('Sales Transactions'!$V$3:$V$82, 'Sales Transactions'!$B$3:$B$82, "2024-01*", 'Sales Transactions'!$L$3:$L$82, $G$4), IF($G$4="All Channels", SUMIFS('Sales Transactions'!$V$3:$V$82, 'Sales Transactions'!$B$3:$B$82, "2024-01*", 'Sales Transactions'!$H$3:$H$82, $C$4), SUMIFS('Sales Transactions'!$V$3:$V$82, 'Sales Transactions'!$B$3:$B$82, "2024-01*", 'Sales Transactions'!$H$3:$H$82, $C$4, 'Sales Transactions'!$L$3:$L$82, $G$4)))) -> 46470 | F46: =IF(C46>0, E46/C46, 0) -> 0.6576 | G46: =IF(AND($C$4="All Basins", $G$4="All Channels"), COUNTIFS('Sales Transactions'!$B$3:$B$82, "2024-01*"), IF($C$4="All Basins", COUNTIFS('Sales Transactions'!$B$3:$B$82, "2024-01*", 'Sales Transactions'!$L$3:$L$82, $G$4), IF($G$4="All Channels", COUNTIFS('Sales Transactions'!$B$3:$B$82, "2024-01*", 'Sales Transactions'!$H$3:$H$82, $C$4), COUNTIFS('Sales Transactions'!$B$3:$B$82, "2024-01*", 'Sales Transactions'!$H$3:$H$82, $C$4, 'Sales Transactions'!$L$3:$L$82, $G$4)))) -> 5 | H46: =IF(C46>0, REPT("█", MIN(8, MAX(1, ROUND(C46/483600*8, 0)))), "") -> █ | I46: Bakken Formation | J46: =IF(AND($C$4<>"All Basins", $C$4<>I46), 0, IF($G$4="All Channels", COUNTIFS('Sales Transactions'!$H$3:$H$82, I46), COUNTIFS('Sales Transactions'!$H$3:$H$82, I46, 'Sales Transactions'!$L$3:$L$82, $G$4))) -> 21 | K46: =IF(AND($C$4<>"All Basins", $C$4<>I46), 0, IF($G$4="All Channels", SUMIFS('Sales Transactions'!$T$3:$T$82, 'Sales Transactions'!$H$3:$H$82, I46), SUMIFS('Sales Transactions'!$T$3:$T$82, 'Sales Transactions'!$H$3:$H$82, I46, 'Sales Transactions'!$L$3:$L$82, $G$4))) -> 869830 | L46: =IF(AND($C$4<>"All Basins", $C$4<>I46), 0, IF($G$4="All Channels", SUMIFS('Sales Transactions'!$U$3:$U$82, 'Sales Transactions'!$H$3:$H$82, I46), SUMIFS('Sales Transactions'!$U$3:$U$82, 'Sales Transactions'!$H$3:$H$82, I46, 'Sales Transactions'!$L$3:$L$82, $G$4))) -> 307500 | M46: =IF(K46>0, N46/K46, 0) -> 0.6465 | N46: =IF(AND($C$4<>"All Basins", $C$4<>I46), 0, IF($G$4="All Channels", SUMIFS('Sales Transactions'!$V$3:$V$82, 'Sales Transactions'!$H$3:$H$82, I46), SUMIFS('Sales Transactions'!$V$3:$V$82, 'Sales Transactions'!$H$3:$H$82, I46, 'Sales Transactions'!$L$3:$L$82, $G$4))) -> 562330 | O46: =IF(K46>0, REPT("■", MIN(8, MAX(1, ROUND(K46/1057245*8, 0)))), "") -> ■■■■■■■
B47: Feb '24 | C47: =IF(AND($C$4="All Basins", $G$4="All Channels"), SUMIFS('Sales Transactions'!$T$3:$T$82, 'Sales Transactions'!$B$3:$B$82, "2024-02*"), IF($C$4="All Basins", SUMIFS('Sales Transactions'!$T$3:$T$82, 'Sales Transactions'!$B$3:$B$82, "2024-02*", 'Sales Transactions'!$L$3:$L$82, $G$4), IF($G$4="All Channels", SUMIFS('Sales Transactions'!$T$3:$T$82, 'Sales Transactions'!$B$3:$B$82, "2024-02*", 'Sales Transactions'!$H$3:$H$82, $C$4), SUMIFS('Sales Transactions'!$T$3:$T$82, 'Sales Transactions'!$B$3:$B$82, "2024-02*", 'Sales Transactions'!$H$3:$H$82, $C$4, 'Sales Transactions'!$L$3:$L$82, $G$4)))) -> 188250 | D47: =C47-E47 -> 65000 | E47: =IF(AND($C$4="All Basins", $G$4="All Channels"), SUMIFS('Sales Transactions'!$V$3:$V$82, 'Sales Transactions'!$B$3:$B$82, "2024-02*"), IF($C$4="All Basins", SUMIFS('Sales Transactions'!$V$3:$V$82, 'Sales Transactions'!$B$3:$B$82, "2024-02*", 'Sales Transactions'!$L$3:$L$82, $G$4), IF($G$4="All Channels", SUMIFS('Sales Transactions'!$V$3:$V$82, 'Sales Transactions'!$B$3:$B$82, "2024-02*", 'Sales Transactions'!$H$3:$H$82, $C$4), SUMIFS('Sales Transactions'!$V$3:$V$82, 'Sales Transactions'!$B$3:$B$82, "2024-02*", 'Sales Transactions'!$H$3:$H$82, $C$4, 'Sales Transactions'!$L$3:$L$82, $G$4)))) -> 123250 | F47: =IF(C47>0, E47/C47, 0) -> 0.6547 | G47: =IF(AND($C$4="All Basins", $G$4="All Channels"), COUNTIFS('Sales Transactions'!$B$3:$B$82, "2024-02*"), IF($C$4="All Basins", COUNTIFS('Sales Transactions'!$B$3:$B$82, "2024-02*", 'Sales Transactions'!$L$3:$L$82, $G$4), IF($G$4="All Channels", COUNTIFS('Sales Transactions'!$B$3:$B$82, "2024-02*", 'Sales Transactions'!$H$3:$H$82, $C$4), COUNTIFS('Sales Transactions'!$B$3:$B$82, "2024-02*", 'Sales Transactions'!$H$3:$H$82, $C$4, 'Sales Transactions'!$L$3:$L$82, $G$4)))) -> 6 | H47: =IF(C47>0, REPT("█", MIN(8, MAX(1, ROUND(C47/483600*8, 0)))), "") -> ███ | I47: Permian Delaware Basin | J47: =IF(AND($C$4<>"All Basins", $C$4<>I47), 0, IF($G$4="All Channels", COUNTIFS('Sales Transactions'!$H$3:$H$82, I47), COUNTIFS('Sales Transactions'!$H$3:$H$82, I47, 'Sales Transactions'!$L$3:$L$82, $G$4))) -> 16 | K47: =IF(AND($C$4<>"All Basins", $C$4<>I47), 0, IF($G$4="All Channels", SUMIFS('Sales Transactions'!$T$3:$T$82, 'Sales Transactions'!$H$3:$H$82, I47), SUMIFS('Sales Transactions'!$T$3:$T$82, 'Sales Transactions'!$H$3:$H$82, I47, 'Sales Transactions'!$L$3:$L$82, $G$4))) -> 1057245 | L47: =IF(AND($C$4<>"All Basins", $C$4<>I47), 0, IF($G$4="All Channels", SUMIFS('Sales Transactions'!$U$3:$U$82, 'Sales Transactions'!$H$3:$H$82, I47), SUMIFS('Sales Transactions'!$U$3:$U$82, 'Sales Transactions'!$H$3:$H$82, I47, 'Sales Transactions'!$L$3:$L$82, $G$4))) -> 387100 | M47: =IF(K47>0, N47/K47, 0) -> 0.6339 | N47: =IF(AND($C$4<>"All Basins", $C$4<>I47), 0, IF($G$4="All Channels", SUMIFS('Sales Transactions'!$V$3:$V$82, 'Sales Transactions'!$H$3:$H$82, I47), SUMIFS('Sales Transactions'!$V$3:$V$82, 'Sales Transactions'!$H$3:$H$82, I47, 'Sales Transactions'!$L$3:$L$82, $G$4))) -> 670145 | O47: =IF(K47>0, REPT("■", MIN(8, MAX(1, ROUND(K47/1057245*8, 0)))), "") -> ■■■■■■■■
B48: Mar '24 | C48: =IF(AND($C$4="All Basins", $G$4="All Channels"), SUMIFS('Sales Transactions'!$T$3:$T$82, 'Sales Transactions'!$B$3:$B$82, "2024-03*"), IF($C$4="All Basins", SUMIFS('Sales Transactions'!$T$3:$T$82, 'Sales Transactions'!$B$3:$B$82, "2024-03*", 'Sales Transactions'!$L$3:$L$82, $G$4), IF($G$4="All Channels", SUMIFS('Sales Transactions'!$T$3:$T$82, 'Sales Transactions'!$B$3:$B$82, "2024-03*", 'Sales Transactions'!$H$3:$H$82, $C$4), SUMIFS('Sales Transactions'!$T$3:$T$82, 'Sales Transactions'!$B$3:$B$82, "2024-03*", 'Sales Transactions'!$H$3:$H$82, $C$4, 'Sales Transactions'!$L$3:$L$82, $G$4)))) -> 77090 | D48: =C48-E48 -> 26500 | E48: =IF(AND($C$4="All Basins", $G$4="All Channels"), SUMIFS('Sales Transactions'!$V$3:$V$82, 'Sales Transactions'!$B$3:$B$82, "2024-03*"), IF($C$4="All Basins", SUMIFS('Sales Transactions'!$V$3:$V$82, 'Sales Transactions'!$B$3:$B$82, "2024-03*", 'Sales Transactions'!$L$3:$L$82, $G$4), IF($G$4="All Channels", SUMIFS('Sales Transactions'!$V$3:$V$82, 'Sales Transactions'!$B$3:$B$82, "2024-03*", 'Sales Transactions'!$H$3:$H$82, $C$4), SUMIFS('Sales Transactions'!$V$3:$V$82, 'Sales Transactions'!$B$3:$B$82, "2024-03*", 'Sales Transactions'!$H$3:$H$82, $C$4, 'Sales Transactions'!$L$3:$L$82, $G$4)))) -> 50590 | F48: =IF(C48>0, E48/C48, 0) -> 0.6562 | G48: =IF(AND($C$4="All Basins", $G$4="All Channels"), COUNTIFS('Sales Transactions'!$B$3:$B$82, "2024-03*"), IF($C$4="All Basins", COUNTIFS('Sales Transactions'!$B$3:$B$82, "2024-03*", 'Sales Transactions'!$L$3:$L$82, $G$4), IF($G$4="All Channels", COUNTIFS('Sales Transactions'!$B$3:$B$82, "2024-03*", 'Sales Transactions'!$H$3:$H$82, $C$4), COUNTIFS('Sales Transactions'!$B$3:$B$82, "2024-03*", 'Sales Transactions'!$H$3:$H$82, $C$4, 'Sales Transactions'!$L$3:$L$82, $G$4)))) -> 3 | H48: =IF(C48>0, REPT("█", MIN(8, MAX(1, ROUND(C48/483600*8, 0)))), "") -> █ | I48: Athabasca Resource Zone | J48: =IF(AND($C$4<>"All Basins", $C$4<>I48), 0, IF($G$4="All Channels", COUNTIFS('Sales Transactions'!$H$3:$H$82, I48), COUNTIFS('Sales Transactions'!$H$3:$H$82, I48, 'Sales Transactions'!$L$3:$L$82, $G$4))) -> 19 | K48: =IF(AND($C$4<>"All Basins", $C$4<>I48), 0, IF($G$4="All Channels", SUMIFS('Sales Transactions'!$T$3:$T$82, 'Sales Transactions'!$H$3:$H$82, I48), SUMIFS('Sales Transactions'!$T$3:$T$82, 'Sales Transactions'!$H$3:$H$82, I48, 'Sales Transactions'!$L$3:$L$82, $G$4))) -> 849275 | L48: =IF(AND($C$4<>"All Basins", $C$4<>I48), 0, IF($G$4="All Channels", SUMIFS('Sales Transactions'!$U$3:$U$82, 'Sales Transactions'!$H$3:$H$82, I48), SUMIFS('Sales Transactions'!$U$3:$U$82, 'Sales Transactions'!$H$3:$H$82, I48, 'Sales Transactions'!$L$3:$L$82, $G$4))) -> 304300 | M48: =IF(K48>0, N48/K48, 0) -> 0.6417 | N48: =IF(AND($C$4<>"All Basins", $C$4<>I48), 0, IF($G$4="All Channels", SUMIFS('Sales Transactions'!$V$3:$V$82, 'Sales Transactions'!$H$3:$H$82, I48), SUMIFS('Sales Transactions'!$V$3:$V$82, 'Sales Transactions'!$H$3:$H$82, I48, 'Sales Transactions'!$L$3:$L$82, $G$4))) -> 544975 | O48: =IF(K48>0, REPT("■", MIN(8, MAX(1, ROUND(K48/1057245*8, 0)))), "") -> ■■■■■■
B49: Apr '24 | C49: =IF(AND($C$4="All Basins", $G$4="All Channels"), SUMIFS('Sales Transactions'!$T$3:$T$82, 'Sales Transactions'!$B$3:$B$82, "2024-04*"), IF($C$4="All Basins", SUMIFS('Sales Transactions'!$T$3:$T$82, 'Sales Transactions'!$B$3:$B$82, "2024-04*", 'Sales Transactions'!$L$3:$L$82, $G$4), IF($G$4="All Channels", SUMIFS('Sales Transactions'!$T$3:$T$82, 'Sales Transactions'!$B$3:$B$82, "2024-04*", 'Sales Transactions'!$H$3:$H$82, $C$4), SUMIFS('Sales Transactions'!$T$3:$T$82, 'Sales Transactions'!$B$3:$B$82, "2024-04*", 'Sales Transactions'!$H$3:$H$82, $C$4, 'Sales Transactions'!$L$3:$L$82, $G$4)))) -> 483600 | D49: =C49-E49 -> 185800 | E49: =IF(AND($C$4="All Basins", $G$4="All Channels"), SUMIFS('Sales Transactions'!$V$3:$V$82, 'Sales Transactions'!$B$3:$B$82, "2024-04*"), IF($C$4="All Basins", SUMIFS('Sales Transactions'!$V$3:$V$82, 'Sales Transactions'!$B$3:$B$82, "2024-04*", 'Sales Transactions'!$L$3:$L$82, $G$4), IF($G$4="All Channels", SUMIFS('Sales Transactions'!$V$3:$V$82, 'Sales Transactions'!$B$3:$B$82, "2024-04*", 'Sales Transactions'!$H$3:$H$82, $C$4), SUMIFS('Sales Transactions'!$V$3:$V$82, 'Sales Transactions'!$B$3:$B$82, "2024-04*", 'Sales Transactions'!$H$3:$H$82, $C$4, 'Sales Transactions'!$L$3:$L$82, $G$4)))) -> 297800 | F49: =IF(C49>0, E49/C49, 0) -> 0.6158 | G49: =IF(AND($C$4="All Basins", $G$4="All Channels"), COUNTIFS('Sales Transactions'!$B$3:$B$82, "2024-04*"), IF($C$4="All Basins", COUNTIFS('Sales Transactions'!$B$3:$B$82, "2024-04*", 'Sales Transactions'!$L$3:$L$82, $G$4), IF($G$4="All Channels", COUNTIFS('Sales Transactions'!$B$3:$B$82, "2024-04*", 'Sales Transactions'!$H$3:$H$82, $C$4), COUNTIFS('Sales Transactions'!$B$3:$B$82, "2024-04*", 'Sales Transactions'!$H$3:$H$82, $C$4, 'Sales Transactions'!$L$3:$L$82, $G$4)))) -> 6 | H49: =IF(C49>0, REPT("█", MIN(8, MAX(1, ROUND(C49/483600*8, 0)))), "") -> ████████ | I49: Eagle Ford Shale Play | J49: =IF(AND($C$4<>"All Basins", $C$4<>I49), 0, IF($G$4="All Channels", COUNTIFS('Sales Transactions'!$H$3:$H$82, I49), COUNTIFS('Sales Transactions'!$H$3:$H$82, I49, 'Sales Transactions'!$L$3:$L$82, $G$4))) -> 13 | K49: =IF(AND($C$4<>"All Basins", $C$4<>I49), 0, IF($G$4="All Channels", SUMIFS('Sales Transactions'!$T$3:$T$82, 'Sales Transactions'!$H$3:$H$82, I49), SUMIFS('Sales Transactions'!$T$3:$T$82, 'Sales Transactions'!$H$3:$H$82, I49, 'Sales Transactions'!$L$3:$L$82, $G$4))) -> 744675 | L49: =IF(AND($C$4<>"All Basins", $C$4<>I49), 0, IF($G$4="All Channels", SUMIFS('Sales Transactions'!$U$3:$U$82, 'Sales Transactions'!$H$3:$H$82, I49), SUMIFS('Sales Transactions'!$U$3:$U$82, 'Sales Transactions'!$H$3:$H$82, I49, 'Sales Transactions'!$L$3:$L$82, $G$4))) -> 288100 | M49: =IF(K49>0, N49/K49, 0) -> 0.6131 | N49: =IF(AND($C$4<>"All Basins", $C$4<>I49), 0, IF($G$4="All Channels", SUMIFS('Sales Transactions'!$V$3:$V$82, 'Sales Transactions'!$H$3:$H$82, I49), SUMIFS('Sales Transactions'!$V$3:$V$82, 'Sales Transactions'!$H$3:$H$82, I49, 'Sales Transactions'!$L$3:$L$82, $G$4))) -> 456575 | O49: =IF(K49>0, REPT("■", MIN(8, MAX(1, ROUND(K49/1057245*8, 0)))), "") -> ■■■■■■
B50: May '24 | C50: =IF(AND($C$4="All Basins", $G$4="All Channels"), SUMIFS('Sales Transactions'!$T$3:$T$82, 'Sales Transactions'!$B$3:$B$82, "2024-05*"), IF($C$4="All Basins", SUMIFS('Sales Transactions'!$T$3:$T$82, 'Sales Transactions'!$B$3:$B$82, "2024-05*", 'Sales Transactions'!$L$3:$L$82, $G$4), IF($G$4="All Channels", SUMIFS('Sales Transactions'!$T$3:$T$82, 'Sales Transactions'!$B$3:$B$82, "2024-05*", 'Sales Transactions'!$H$3:$H$82, $C$4), SUMIFS('Sales Transactions'!$T$3:$T$82, 'Sales Transactions'!$B$3:$B$82, "2024-05*", 'Sales Transactions'!$H$3:$H$82, $C$4, 'Sales Transactions'!$L$3:$L$82, $G$4)))) -> 321375 | D50: =C50-E50 -> 116800 | E50: =IF(AND($C$4="All Basins", $G$4="All Channels"), SUMIFS('Sales Transactions'!$V$3:$V$82, 'Sales Transactions'!$B$3:$B$82, "2024-05*"), IF($C$4="All Basins", SUMIFS('Sales Transactions'!$V$3:$V$82, 'Sales Transactions'!$B$3:$B$82, "2024-05*", 'Sales Transactions'!$L$3:$L$82, $G$4), IF($G$4="All Channels", SUMIFS('Sales Transactions'!$V$3:$V$82, 'Sales Transactions'!$B$3:$B$82, "2024-05*", 'Sales Transactions'!$H$3:$H$82, $C$4), SUMIFS('Sales Transactions'!$V$3:$V$82, 'Sales Transactions'!$B$3:$B$82, "2024-05*", 'Sales Transactions'!$H$3:$H$82, $C$4, 'Sales Transactions'!$L$3:$L$82, $G$4)))) -> 204575 | F50: =IF(C50>0, E50/C50, 0) -> 0.6366 | G50: =IF(AND($C$4="All Basins", $G$4="All Channels"), COUNTIFS('Sales Transactions'!$B$3:$B$82, "2024-05*"), IF($C$4="All Basins", COUNTIFS('Sales Transactions'!$B$3:$B$82, "2024-05*", 'Sales Transactions'!$L$3:$L$82, $G$4), IF($G$4="All Channels", COUNTIFS('Sales Transactions'!$B$3:$B$82, "2024-05*", 'Sales Transactions'!$H$3:$H$82, $C$4), COUNTIFS('Sales Transactions'!$B$3:$B$82, "2024-05*", 'Sales Transactions'!$H$3:$H$82, $C$4, 'Sales Transactions'!$L$3:$L$82, $G$4)))) -> 3 | H50: =IF(C50>0, REPT("█", MIN(8, MAX(1, ROUND(C50/483600*8, 0)))), "") -> █████ | I50: Total: | J50: =SUM(J46:J49) -> 80 | K50: =SUM(K46:K49) -> 3769345 | L50: =SUM(L46:L49) -> 1376900 | M50: =IF(K50>0, N50/K50, 0) -> 0.6347 | N50: =SUM(N46:N49) -> 2392445 | O50: 100% Portfolio
B51: Jun '24 | C51: =IF(AND($C$4="All Basins", $G$4="All Channels"), SUMIFS('Sales Transactions'!$T$3:$T$82, 'Sales Transactions'!$B$3:$B$82, "2024-06*"), IF($C$4="All Basins", SUMIFS('Sales Transactions'!$T$3:$T$82, 'Sales Transactions'!$B$3:$B$82, "2024-06*", 'Sales Transactions'!$L$3:$L$82, $G$4), IF($G$4="All Channels", SUMIFS('Sales Transactions'!$T$3:$T$82, 'Sales Transactions'!$B$3:$B$82, "2024-06*", 'Sales Transactions'!$H$3:$H$82, $C$4), SUMIFS('Sales Transactions'!$T$3:$T$82, 'Sales Transactions'!$B$3:$B$82, "2024-06*", 'Sales Transactions'!$H$3:$H$82, $C$4, 'Sales Transactions'!$L$3:$L$82, $G$4)))) -> 110425 | D51: =C51-E51 -> 40300 | E51: =IF(AND($C$4="All Basins", $G$4="All Channels"), SUMIFS('Sales Transactions'!$V$3:$V$82, 'Sales Transactions'!$B$3:$B$82, "2024-06*"), IF($C$4="All Basins", SUMIFS('Sales Transactions'!$V$3:$V$82, 'Sales Transactions'!$B$3:$B$82, "2024-06*", 'Sales Transactions'!$L$3:$L$82, $G$4), IF($G$4="All Channels", SUMIFS('Sales Transactions'!$V$3:$V$82, 'Sales Transactions'!$B$3:$B$82, "2024-06*", 'Sales Transactions'!$H$3:$H$82, $C$4), SUMIFS('Sales Transactions'!$V$3:$V$82, 'Sales Transactions'!$B$3:$B$82, "2024-06*", 'Sales Transactions'!$H$3:$H$82, $C$4, 'Sales Transactions'!$L$3:$L$82, $G$4)))) -> 70125 | F51: =IF(C51>0, E51/C51, 0) -> 0.635 | G51: =IF(AND($C$4="All Basins", $G$4="All Channels"), COUNTIFS('Sales Transactions'!$B$3:$B$82, "2024-06*"), IF($C$4="All Basins", COUNTIFS('Sales Transactions'!$B$3:$B$82, "2024-06*", 'Sales Transactions'!$L$3:$L$82, $G$4), IF($G$4="All Channels", COUNTIFS('Sales Transactions'!$B$3:$B$82, "2024-06*", 'Sales Transactions'!$H$3:$H$82, $C$4), COUNTIFS('Sales Transactions'!$B$3:$B$82, "2024-06*", 'Sales Transactions'!$H$3:$H$82, $C$4, 'Sales Transactions'!$L$3:$L$82, $G$4)))) -> 4 | H51: =IF(C51>0, REPT("█", MIN(8, MAX(1, ROUND(C51/483600*8, 0)))), "") -> ██ | I51: TOP STRATEGIC RIG ASSET / EXTRACTION WELLS BY VALUE
B52: Jul '24 | C52: =IF(AND($C$4="All Basins", $G$4="All Channels"), SUMIFS('Sales Transactions'!$T$3:$T$82, 'Sales Transactions'!$B$3:$B$82, "2024-07*"), IF($C$4="All Basins", SUMIFS('Sales Transactions'!$T$3:$T$82, 'Sales Transactions'!$B$3:$B$82, "2024-07*", 'Sales Transactions'!$L$3:$L$82, $G$4), IF($G$4="All Channels", SUMIFS('Sales Transactions'!$T$3:$T$82, 'Sales Transactions'!$B$3:$B$82, "2024-07*", 'Sales Transactions'!$H$3:$H$82, $C$4), SUMIFS('Sales Transactions'!$T$3:$T$82, 'Sales Transactions'!$B$3:$B$82, "2024-07*", 'Sales Transactions'!$H$3:$H$82, $C$4, 'Sales Transactions'!$L$3:$L$82, $G$4)))) -> 226315 | D52: =C52-E52 -> 78900 | E52: =IF(AND($C$4="All Basins", $G$4="All Channels"), SUMIFS('Sales Transactions'!$V$3:$V$82, 'Sales Transactions'!$B$3:$B$82, "2024-07*"), IF($C$4="All Basins", SUMIFS('Sales Transactions'!$V$3:$V$82, 'Sales Transactions'!$B$3:$B$82, "2024-07*", 'Sales Transactions'!$L$3:$L$82, $G$4), IF($G$4="All Channels", SUMIFS('Sales Transactions'!$V$3:$V$82, 'Sales Transactions'!$B$3:$B$82, "2024-07*", 'Sales Transactions'!$H$3:$H$82, $C$4), SUMIFS('Sales Transactions'!$V$3:$V$82, 'Sales Transactions'!$B$3:$B$82, "2024-07*", 'Sales Transactions'!$H$3:$H$82, $C$4, 'Sales Transactions'!$L$3:$L$82, $G$4)))) -> 147415 | F52: =IF(C52>0, E52/C52, 0) -> 0.6514 | G52: =IF(AND($C$4="All Basins", $G$4="All Channels"), COUNTIFS('Sales Transactions'!$B$3:$B$82, "2024-07*"), IF($C$4="All Basins", COUNTIFS('Sales Transactions'!$B$3:$B$82, "2024-07*", 'Sales Transactions'!$L$3:$L$82, $G$4), IF($G$4="All Channels", COUNTIFS('Sales Transactions'!$B$3:$B$82, "2024-07*", 'Sales Transactions'!$H$3:$H$82, $C$4), COUNTIFS('Sales Transactions'!$B$3:$B$82, "2024-07*", 'Sales Transactions'!$H$3:$H$82, $C$4, 'Sales Transactions'!$L$3:$L$82, $G$4)))) -> 4 | H52: =IF(C52>0, REPT("█", MIN(8, MAX(1, ROUND(C52/483600*8, 0)))), "") -> ████ | I52: Rig Asset / Extraction Well | L52: Tier | M52: Orders | N52: Revenue | O52: Health
B53: Aug '24 | C53: =IF(AND($C$4="All Basins", $G$4="All Channels"), SUMIFS('Sales Transactions'!$T$3:$T$82, 'Sales Transactions'!$B$3:$B$82, "2024-08*"), IF($C$4="All Basins", SUMIFS('Sales Transactions'!$T$3:$T$82, 'Sales Transactions'!$B$3:$B$82, "2024-08*", 'Sales Transactions'!$L$3:$L$82, $G$4), IF($G$4="All Channels", SUMIFS('Sales Transactions'!$T$3:$T$82, 'Sales Transactions'!$B$3:$B$82, "2024-08*", 'Sales Transactions'!$H$3:$H$82, $C$4), SUMIFS('Sales Transactions'!$T$3:$T$82, 'Sales Transactions'!$B$3:$B$82, "2024-08*", 'Sales Transactions'!$H$3:$H$82, $C$4, 'Sales Transactions'!$L$3:$L$82, $G$4)))) -> 272750 | D53: =C53-E53 -> 100200 | E53: =IF(AND($C$4="All Basins", $G$4="All Channels"), SUMIFS('Sales Transactions'!$V$3:$V$82, 'Sales Transactions'!$B$3:$B$82, "2024-08*"), IF($C$4="All Basins", SUMIFS('Sales Transactions'!$V$3:$V$82, 'Sales Transactions'!$B$3:$B$82, "2024-08*", 'Sales Transactions'!$L$3:$L$82, $G$4), IF($G$4="All Channels", SUMIFS('Sales Transactions'!$V$3:$V$82, 'Sales Transactions'!$B$3:$B$82, "2024-08*", 'Sales Transactions'!$H$3:$H$82, $C$4), SUMIFS('Sales Transactions'!$V$3:$V$82, 'Sales Transactions'!$B$3:$B$82, "2024-08*", 'Sales Transactions'!$H$3:$H$82, $C$4, 'Sales Transactions'!$L$3:$L$82, $G$4)))) -> 172550 | F53: =IF(C53>0, E53/C53, 0) -> 0.6326 | G53: =IF(AND($C$4="All Basins", $G$4="All Channels"), COUNTIFS('Sales Transactions'!$B$3:$B$82, "2024-08*"), IF($C$4="All Basins", COUNTIFS('Sales Transactions'!$B$3:$B$82, "2024-08*", 'Sales Transactions'!$L$3:$L$82, $G$4), IF($G$4="All Channels", COUNTIFS('Sales Transactions'!$B$3:$B$82, "2024-08*", 'Sales Transactions'!$H$3:$H$82, $C$4), COUNTIFS('Sales Transactions'!$B$3:$B$82, "2024-08*", 'Sales Transactions'!$H$3:$H$82, $C$4, 'Sales Transactions'!$L$3:$L$82, $G$4)))) -> 3 | H53: =IF(C53>0, REPT("█", MIN(8, MAX(1, ROUND(C53/483600*8, 0)))), "") -> █████ | I53: Rio Tinto Critical Minerals | L53: Corporate | M53: =IF(AND($C$4="All Basins", $G$4="All Channels"), COUNTIFS('Sales Transactions'!$E$3:$E$82, I53), IF($C$4="All Basins", COUNTIFS('Sales Transactions'!$E$3:$E$82, I53, 'Sales Transactions'!$L$3:$L$82, $G$4), IF($G$4="All Channels", COUNTIFS('Sales Transactions'!$E$3:$E$82, I53, 'Sales Transactions'!$H$3:$H$82, $C$4), COUNTIFS('Sales Transactions'!$E$3:$E$82, I53, 'Sales Transactions'!$H$3:$H$82, $C$4, 'Sales Transactions'!$L$3:$L$82, $G$4)))) -> 15 | N53: =IF(AND($C$4="All Basins", $G$4="All Channels"), SUMIFS('Sales Transactions'!$T$3:$T$82, 'Sales Transactions'!$E$3:$E$82, I53), IF($C$4="All Basins", SUMIFS('Sales Transactions'!$T$3:$T$82, 'Sales Transactions'!$E$3:$E$82, I53, 'Sales Transactions'!$L$3:$L$82, $G$4), IF($G$4="All Channels", SUMIFS('Sales Transactions'!$T$3:$T$82, 'Sales Transactions'!$E$3:$E$82, I53, 'Sales Transactions'!$H$3:$H$82, $C$4), SUMIFS('Sales Transactions'!$T$3:$T$82, 'Sales Transactions'!$E$3:$E$82, I53, 'Sales Transactions'!$H$3:$H$82, $C$4, 'Sales Transactions'!$L$3:$L$82, $G$4)))) -> 1060545 | O53: Optimal
B54: Sep '24 | C54: =IF(AND($C$4="All Basins", $G$4="All Channels"), SUMIFS('Sales Transactions'!$T$3:$T$82, 'Sales Transactions'!$B$3:$B$82, "2024-09*"), IF($C$4="All Basins", SUMIFS('Sales Transactions'!$T$3:$T$82, 'Sales Transactions'!$B$3:$B$82, "2024-09*", 'Sales Transactions'!$L$3:$L$82, $G$4), IF($G$4="All Channels", SUMIFS('Sales Transactions'!$T$3:$T$82, 'Sales Transactions'!$B$3:$B$82, "2024-09*", 'Sales Transactions'!$H$3:$H$82, $C$4), SUMIFS('Sales Transactions'!$T$3:$T$82, 'Sales Transactions'!$B$3:$B$82, "2024-09*", 'Sales Transactions'!$H$3:$H$82, $C$4, 'Sales Transactions'!$L$3:$L$82, $G$4)))) -> 163470 | D54: =C54-E54 -> 56300 | E54: =IF(AND($C$4="All Basins", $G$4="All Channels"), SUMIFS('Sales Transactions'!$V$3:$V$82, 'Sales Transactions'!$B$3:$B$82, "2024-09*"), IF($C$4="All Basins", SUMIFS('Sales Transactions'!$V$3:$V$82, 'Sales Transactions'!$B$3:$B$82, "2024-09*", 'Sales Transactions'!$L$3:$L$82, $G$4), IF($G$4="All Channels", SUMIFS('Sales Transactions'!$V$3:$V$82, 'Sales Transactions'!$B$3:$B$82, "2024-09*", 'Sales Transactions'!$H$3:$H$82, $C$4), SUMIFS('Sales Transactions'!$V$3:$V$82, 'Sales Transactions'!$B$3:$B$82, "2024-09*", 'Sales Transactions'!$H$3:$H$82, $C$4, 'Sales Transactions'!$L$3:$L$82, $G$4)))) -> 107170 | F54: =IF(C54>0, E54/C54, 0) -> 0.6556 | G54: =IF(AND($C$4="All Basins", $G$4="All Channels"), COUNTIFS('Sales Transactions'!$B$3:$B$82, "2024-09*"), IF($C$4="All Basins", COUNTIFS('Sales Transactions'!$B$3:$B$82, "2024-09*", 'Sales Transactions'!$L$3:$L$82, $G$4), IF($G$4="All Channels", COUNTIFS('Sales Transactions'!$B$3:$B$82, "2024-09*", 'Sales Transactions'!$H$3:$H$82, $C$4), COUNTIFS('Sales Transactions'!$B$3:$B$82, "2024-09*", 'Sales Transactions'!$H$3:$H$82, $C$4, 'Sales Transactions'!$L$3:$L$82, $G$4)))) -> 5 | H54: =IF(C54>0, REPT("█", MIN(8, MAX(1, ROUND(C54/483600*8, 0)))), "") -> ███ | I54: Shell Integrated Gas Ventures | L54: Strategic | M54: =IF(AND($C$4="All Basins", $G$4="All Channels"), COUNTIFS('Sales Transactions'!$E$3:$E$82, I54), IF($C$4="All Basins", COUNTIFS('Sales Transactions'!$E$3:$E$82, I54, 'Sales Transactions'!$L$3:$L$82, $G$4), IF($G$4="All Channels", COUNTIFS('Sales Transactions'!$E$3:$E$82, I54, 'Sales Transactions'!$H$3:$H$82, $C$4), COUNTIFS('Sales Transactions'!$E$3:$E$82, I54, 'Sales Transactions'!$H$3:$H$82, $C$4, 'Sales Transactions'!$L$3:$L$82, $G$4)))) -> 20 | N54: =IF(AND($C$4="All Basins", $G$4="All Channels"), SUMIFS('Sales Transactions'!$T$3:$T$82, 'Sales Transactions'!$E$3:$E$82, I54), IF($C$4="All Basins", SUMIFS('Sales Transactions'!$T$3:$T$82, 'Sales Transactions'!$E$3:$E$82, I54, 'Sales Transactions'!$L$3:$L$82, $G$4), IF($G$4="All Channels", SUMIFS('Sales Transactions'!$T$3:$T$82, 'Sales Transactions'!$E$3:$E$82, I54, 'Sales Transactions'!$H$3:$H$82, $C$4), SUMIFS('Sales Transactions'!$T$3:$T$82, 'Sales Transactions'!$E$3:$E$82, I54, 'Sales Transactions'!$H$3:$H$82, $C$4, 'Sales Transactions'!$L$3:$L$82, $G$4)))) -> 683315 | O54: Optimal
B55: Nov '24 | C55: =IF(AND($C$4="All Basins", $G$4="All Channels"), SUMIFS('Sales Transactions'!$T$3:$T$82, 'Sales Transactions'!$B$3:$B$82, "2024-11*"), IF($C$4="All Basins", SUMIFS('Sales Transactions'!$T$3:$T$82, 'Sales Transactions'!$B$3:$B$82, "2024-11*", 'Sales Transactions'!$L$3:$L$82, $G$4), IF($G$4="All Channels", SUMIFS('Sales Transactions'!$T$3:$T$82, 'Sales Transactions'!$B$3:$B$82, "2024-11*", 'Sales Transactions'!$H$3:$H$82, $C$4), SUMIFS('Sales Transactions'!$T$3:$T$82, 'Sales Transactions'!$B$3:$B$82, "2024-11*", 'Sales Transactions'!$H$3:$H$82, $C$4, 'Sales Transactions'!$L$3:$L$82, $G$4)))) -> 135170 | D55: =C55-E55 -> 48200 | E55: =IF(AND($C$4="All Basins", $G$4="All Channels"), SUMIFS('Sales Transactions'!$V$3:$V$82, 'Sales Transactions'!$B$3:$B$82, "2024-11*"), IF($C$4="All Basins", SUMIFS('Sales Transactions'!$V$3:$V$82, 'Sales Transactions'!$B$3:$B$82, "2024-11*", 'Sales Transactions'!$L$3:$L$82, $G$4), IF($G$4="All Channels", SUMIFS('Sales Transactions'!$V$3:$V$82, 'Sales Transactions'!$B$3:$B$82, "2024-11*", 'Sales Transactions'!$H$3:$H$82, $C$4), SUMIFS('Sales Transactions'!$V$3:$V$82, 'Sales Transactions'!$B$3:$B$82, "2024-11*", 'Sales Transactions'!$H$3:$H$82, $C$4, 'Sales Transactions'!$L$3:$L$82, $G$4)))) -> 86970 | F55: =IF(C55>0, E55/C55, 0) -> 0.6434 | G55: =IF(AND($C$4="All Basins", $G$4="All Channels"), COUNTIFS('Sales Transactions'!$B$3:$B$82, "2024-11*"), IF($C$4="All Basins", COUNTIFS('Sales Transactions'!$B$3:$B$82, "2024-11*", 'Sales Transactions'!$L$3:$L$82, $G$4), IF($G$4="All Channels", COUNTIFS('Sales Transactions'!$B$3:$B$82, "2024-11*", 'Sales Transactions'!$H$3:$H$82, $C$4), COUNTIFS('Sales Transactions'!$B$3:$B$82, "2024-11*", 'Sales Transactions'!$H$3:$H$82, $C$4, 'Sales Transactions'!$L$3:$L$82, $G$4)))) -> 4 | H55: =IF(C55>0, REPT("█", MIN(8, MAX(1, ROUND(C55/483600*8, 0)))), "") -> ██ | I55: TotalEnergies Subsea R&D | L55: Mid-Market | M55: =IF(AND($C$4="All Basins", $G$4="All Channels"), COUNTIFS('Sales Transactions'!$E$3:$E$82, I55), IF($C$4="All Basins", COUNTIFS('Sales Transactions'!$E$3:$E$82, I55, 'Sales Transactions'!$L$3:$L$82, $G$4), IF($G$4="All Channels", COUNTIFS('Sales Transactions'!$E$3:$E$82, I55, 'Sales Transactions'!$H$3:$H$82, $C$4), COUNTIFS('Sales Transactions'!$E$3:$E$82, I55, 'Sales Transactions'!$H$3:$H$82, $C$4, 'Sales Transactions'!$L$3:$L$82, $G$4)))) -> 8 | N55: =IF(AND($C$4="All Basins", $G$4="All Channels"), SUMIFS('Sales Transactions'!$T$3:$T$82, 'Sales Transactions'!$E$3:$E$82, I55), IF($C$4="All Basins", SUMIFS('Sales Transactions'!$T$3:$T$82, 'Sales Transactions'!$E$3:$E$82, I55, 'Sales Transactions'!$L$3:$L$82, $G$4), IF($G$4="All Channels", SUMIFS('Sales Transactions'!$T$3:$T$82, 'Sales Transactions'!$E$3:$E$82, I55, 'Sales Transactions'!$H$3:$H$82, $C$4), SUMIFS('Sales Transactions'!$T$3:$T$82, 'Sales Transactions'!$E$3:$E$82, I55, 'Sales Transactions'!$H$3:$H$82, $C$4, 'Sales Transactions'!$L$3:$L$82, $G$4)))) -> 613300 | O55: Optimal
B56: Dec '24 | C56: =IF(AND($C$4="All Basins", $G$4="All Channels"), SUMIFS('Sales Transactions'!$T$3:$T$82, 'Sales Transactions'!$B$3:$B$82, "2024-12*"), IF($C$4="All Basins", SUMIFS('Sales Transactions'!$T$3:$T$82, 'Sales Transactions'!$B$3:$B$82, "2024-12*", 'Sales Transactions'!$L$3:$L$82, $G$4), IF($G$4="All Channels", SUMIFS('Sales Transactions'!$T$3:$T$82, 'Sales Transactions'!$B$3:$B$82, "2024-12*", 'Sales Transactions'!$H$3:$H$82, $C$4), SUMIFS('Sales Transactions'!$T$3:$T$82, 'Sales Transactions'!$B$3:$B$82, "2024-12*", 'Sales Transactions'!$H$3:$H$82, $C$4, 'Sales Transactions'!$L$3:$L$82, $G$4)))) -> 300450 | D56: =C56-E56 -> 113000 | E56: =IF(AND($C$4="All Basins", $G$4="All Channels"), SUMIFS('Sales Transactions'!$V$3:$V$82, 'Sales Transactions'!$B$3:$B$82, "2024-12*"), IF($C$4="All Basins", SUMIFS('Sales Transactions'!$V$3:$V$82, 'Sales Transactions'!$B$3:$B$82, "2024-12*", 'Sales Transactions'!$L$3:$L$82, $G$4), IF($G$4="All Channels", SUMIFS('Sales Transactions'!$V$3:$V$82, 'Sales Transactions'!$B$3:$B$82, "2024-12*", 'Sales Transactions'!$H$3:$H$82, $C$4), SUMIFS('Sales Transactions'!$V$3:$V$82, 'Sales Transactions'!$B$3:$B$82, "2024-12*", 'Sales Transactions'!$H$3:$H$82, $C$4, 'Sales Transactions'!$L$3:$L$82, $G$4)))) -> 187450 | F56: =IF(C56>0, E56/C56, 0) -> 0.6239 | G56: =IF(AND($C$4="All Basins", $G$4="All Channels"), COUNTIFS('Sales Transactions'!$B$3:$B$82, "2024-12*"), IF($C$4="All Basins", COUNTIFS('Sales Transactions'!$B$3:$B$82, "2024-12*", 'Sales Transactions'!$L$3:$L$82, $G$4), IF($G$4="All Channels", COUNTIFS('Sales Transactions'!$B$3:$B$82, "2024-12*", 'Sales Transactions'!$H$3:$H$82, $C$4), COUNTIFS('Sales Transactions'!$B$3:$B$82, "2024-12*", 'Sales Transactions'!$H$3:$H$82, $C$4, 'Sales Transactions'!$L$3:$L$82, $G$4)))) -> 3 | H56: =IF(C56>0, REPT("█", MIN(8, MAX(1, ROUND(C56/483600*8, 0)))), "") -> █████ | I56: Chevron Global Upstream | L56: Strategic | M56: =IF(AND($C$4="All Basins", $G$4="All Channels"), COUNTIFS('Sales Transactions'!$E$3:$E$82, I56), IF($C$4="All Basins", COUNTIFS('Sales Transactions'!$E$3:$E$82, I56, 'Sales Transactions'!$L$3:$L$82, $G$4), IF($G$4="All Channels", COUNTIFS('Sales Transactions'!$E$3:$E$82, I56, 'Sales Transactions'!$H$3:$H$82, $C$4), COUNTIFS('Sales Transactions'!$E$3:$E$82, I56, 'Sales Transactions'!$H$3:$H$82, $C$4, 'Sales Transactions'!$L$3:$L$82, $G$4)))) -> 21 | N56: =IF(AND($C$4="All Basins", $G$4="All Channels"), SUMIFS('Sales Transactions'!$T$3:$T$82, 'Sales Transactions'!$E$3:$E$82, I56), IF($C$4="All Basins", SUMIFS('Sales Transactions'!$T$3:$T$82, 'Sales Transactions'!$E$3:$E$82, I56, 'Sales Transactions'!$L$3:$L$82, $G$4), IF($G$4="All Channels", SUMIFS('Sales Transactions'!$T$3:$T$82, 'Sales Transactions'!$E$3:$E$82, I56, 'Sales Transactions'!$H$3:$H$82, $C$4), SUMIFS('Sales Transactions'!$T$3:$T$82, 'Sales Transactions'!$E$3:$E$82, I56, 'Sales Transactions'!$H$3:$H$82, $C$4, 'Sales Transactions'!$L$3:$L$82, $G$4)))) -> 569965 | O56: Optimal
B57: Jan '25 | C57: =IF(AND($C$4="All Basins", $G$4="All Channels"), SUMIFS('Sales Transactions'!$T$3:$T$82, 'Sales Transactions'!$B$3:$B$82, "2025-01*"), IF($C$4="All Basins", SUMIFS('Sales Transactions'!$T$3:$T$82, 'Sales Transactions'!$B$3:$B$82, "2025-01*", 'Sales Transactions'!$L$3:$L$82, $G$4), IF($G$4="All Channels", SUMIFS('Sales Transactions'!$T$3:$T$82, 'Sales Transactions'!$B$3:$B$82, "2025-01*", 'Sales Transactions'!$H$3:$H$82, $C$4), SUMIFS('Sales Transactions'!$T$3:$T$82, 'Sales Transactions'!$B$3:$B$82, "2025-01*", 'Sales Transactions'!$H$3:$H$82, $C$4, 'Sales Transactions'!$L$3:$L$82, $G$4)))) -> 360000 | D57: =C57-E57 -> 135800 | E57: =IF(AND($C$4="All Basins", $G$4="All Channels"), SUMIFS('Sales Transactions'!$V$3:$V$82, 'Sales Transactions'!$B$3:$B$82, "2025-01*"), IF($C$4="All Basins", SUMIFS('Sales Transactions'!$V$3:$V$82, 'Sales Transactions'!$B$3:$B$82, "2025-01*", 'Sales Transactions'!$L$3:$L$82, $G$4), IF($G$4="All Channels", SUMIFS('Sales Transactions'!$V$3:$V$82, 'Sales Transactions'!$B$3:$B$82, "2025-01*", 'Sales Transactions'!$H$3:$H$82, $C$4), SUMIFS('Sales Transactions'!$V$3:$V$82, 'Sales Transactions'!$B$3:$B$82, "2025-01*", 'Sales Transactions'!$H$3:$H$82, $C$4, 'Sales Transactions'!$L$3:$L$82, $G$4)))) -> 224200 | F57: =IF(C57>0, E57/C57, 0) -> 0.6228 | G57: =IF(AND($C$4="All Basins", $G$4="All Channels"), COUNTIFS('Sales Transactions'!$B$3:$B$82, "2025-01*"), IF($C$4="All Basins", COUNTIFS('Sales Transactions'!$B$3:$B$82, "2025-01*", 'Sales Transactions'!$L$3:$L$82, $G$4), IF($G$4="All Channels", COUNTIFS('Sales Transactions'!$B$3:$B$82, "2025-01*", 'Sales Transactions'!$H$3:$H$82, $C$4), COUNTIFS('Sales Transactions'!$B$3:$B$82, "2025-01*", 'Sales Transactions'!$H$3:$H$82, $C$4, 'Sales Transactions'!$L$3:$L$82, $G$4)))) -> 5 | H57: =IF(C57>0, REPT("█", MIN(8, MAX(1, ROUND(C57/483600*8, 0)))), "") -> ██████ | I57: BHP Billiton Metals Exploration | L57: Corporate | M57: =IF(AND($C$4="All Basins", $G$4="All Channels"), COUNTIFS('Sales Transactions'!$E$3:$E$82, I57), IF($C$4="All Basins", COUNTIFS('Sales Transactions'!$E$3:$E$82, I57, 'Sales Transactions'!$L$3:$L$82, $G$4), IF($G$4="All Channels", COUNTIFS('Sales Transactions'!$E$3:$E$82, I57, 'Sales Transactions'!$H$3:$H$82, $C$4), COUNTIFS('Sales Transactions'!$E$3:$E$82, I57, 'Sales Transactions'!$H$3:$H$82, $C$4, 'Sales Transactions'!$L$3:$L$82, $G$4)))) -> 10 | N57: =IF(AND($C$4="All Basins", $G$4="All Channels"), SUMIFS('Sales Transactions'!$T$3:$T$82, 'Sales Transactions'!$E$3:$E$82, I57), IF($C$4="All Basins", SUMIFS('Sales Transactions'!$T$3:$T$82, 'Sales Transactions'!$E$3:$E$82, I57, 'Sales Transactions'!$L$3:$L$82, $G$4), IF($G$4="All Channels", SUMIFS('Sales Transactions'!$T$3:$T$82, 'Sales Transactions'!$E$3:$E$82, I57, 'Sales Transactions'!$H$3:$H$82, $C$4), SUMIFS('Sales Transactions'!$T$3:$T$82, 'Sales Transactions'!$E$3:$E$82, I57, 'Sales Transactions'!$H$3:$H$82, $C$4, 'Sales Transactions'!$L$3:$L$82, $G$4)))) -> 470430 | O57: Stable
B58: Total LTM: | C58: =SUM(C46:C57) -> 3769345 | D58: =SUM(D46:D57) -> 1376900 | E58: =SUM(E46:E57) -> 2392445 | F58: =IF(C58>0, E58/C58, 0) -> 0.6347 | G58: =SUM(G46:G57) -> 80 | H58: 100.0% | I58: Top Strategic Total: | L58: 5 Accounts | M58: =SUM(M53:M57) -> 74 | N58: =SUM(N53:N57) -> 3397555 | O58: 100% Retained
B60: COMMODITY RESOURCE TYPE PORTFOLIO & MARGIN DIRECTORY | I60: CHANNEL UPSTREAM PRODUCTION REVENUE DISTRIBUTION & MIX MATRIX
B61: Commodity Resource Type | C61: Volume / Units | D61: Upstream Production Revenue | E61: Share % | F61: Net Crack Spread & Refining Margin | G61: Extraction Safety Adherence % | H61: Volume Bar | I61: Channel | J61: Volume Mix | K61: Channel Upstream Production Revenue | L61: Est. Net Crack Spread & Refining Margin | M61: Margin % | N61: Status | O61: Mix Bar
B62: Drilling Hardware | C62: =IF(AND($C$4="All Basins", $G$4="All Channels"), SUMIFS('Sales Transactions'!$R$3:$R$82, 'Sales Transactions'!$O$3:$O$82, B62), IF($C$4="All Basins", SUMIFS('Sales Transactions'!$R$3:$R$82, 'Sales Transactions'!$O$3:$O$82, B62, 'Sales Transactions'!$L$3:$L$82, $G$4), IF($G$4="All Channels", SUMIFS('Sales Transactions'!$R$3:$R$82, 'Sales Transactions'!$O$3:$O$82, B62, 'Sales Transactions'!$H$3:$H$82, $C$4), SUMIFS('Sales Transactions'!$R$3:$R$82, 'Sales Transactions'!$O$3:$O$82, B62, 'Sales Transactions'!$H$3:$H$82, $C$4, 'Sales Transactions'!$L$3:$L$82, $G$4)))) -> 66 | D62: =IF(AND($C$4="All Basins", $G$4="All Channels"), SUMIFS('Sales Transactions'!$T$3:$T$82, 'Sales Transactions'!$O$3:$O$82, B62), IF($C$4="All Basins", SUMIFS('Sales Transactions'!$T$3:$T$82, 'Sales Transactions'!$O$3:$O$82, B62, 'Sales Transactions'!$L$3:$L$82, $G$4), IF($G$4="All Channels", SUMIFS('Sales Transactions'!$T$3:$T$82, 'Sales Transactions'!$O$3:$O$82, B62, 'Sales Transactions'!$H$3:$H$82, $C$4), SUMIFS('Sales Transactions'!$T$3:$T$82, 'Sales Transactions'!$O$3:$O$82, B62, 'Sales Transactions'!$H$3:$H$82, $C$4, 'Sales Transactions'!$L$3:$L$82, $G$4)))) -> 1427500 | E62: =IF($D$67>0, D62/$D$67, 0) -> 0.3787 | F62: =IF(AND($C$4="All Basins", $G$4="All Channels"), SUMIFS('Sales Transactions'!$V$3:$V$82, 'Sales Transactions'!$O$3:$O$82, B62), IF($C$4="All Basins", SUMIFS('Sales Transactions'!$V$3:$V$82, 'Sales Transactions'!$O$3:$O$82, B62, 'Sales Transactions'!$L$3:$L$82, $G$4), IF($G$4="All Channels", SUMIFS('Sales Transactions'!$V$3:$V$82, 'Sales Transactions'!$O$3:$O$82, B62, 'Sales Transactions'!$H$3:$H$82, $C$4), SUMIFS('Sales Transactions'!$V$3:$V$82, 'Sales Transactions'!$O$3:$O$82, B62, 'Sales Transactions'!$H$3:$H$82, $C$4, 'Sales Transactions'!$L$3:$L$82, $G$4)))) -> 886300 | G62: =IF(D62>0, F62/D62, 0) -> 0.6209 | H62: =IF(D62>0, REPT("█", MIN(8, MAX(1, ROUND(D62/1427500*8, 0)))), "") -> ████████ | I62: Export LNG Terminal | J62: =IF($K$66>0, K62/$K$66, 0) -> 0.317 | K62: =IF(AND($G$4<>"All Channels", $G$4<>I62), 0, IF($C$4="All Basins", SUMIFS('Sales Transactions'!$T$3:$T$82, 'Sales Transactions'!$L$3:$L$82, I62), SUMIFS('Sales Transactions'!$T$3:$T$82, 'Sales Transactions'!$L$3:$L$82, I62, 'Sales Transactions'!$H$3:$H$82, $C$4))) -> 1194420 | L62: =IF(AND($G$4<>"All Channels", $G$4<>I62), 0, IF($C$4="All Basins", SUMIFS('Sales Transactions'!$V$3:$V$82, 'Sales Transactions'!$L$3:$L$82, I62), SUMIFS('Sales Transactions'!$V$3:$V$82, 'Sales Transactions'!$L$3:$L$82, I62, 'Sales Transactions'!$H$3:$H$82, $C$4))) -> 751220 | M62: =IF(K62>0, L62/K62, 0) -> 0.62894124 | N62: Primary | O62: ■■■■■
B63: Gas Processing | C63: =IF(AND($C$4="All Basins", $G$4="All Channels"), SUMIFS('Sales Transactions'!$R$3:$R$82, 'Sales Transactions'!$O$3:$O$82, B63), IF($C$4="All Basins", SUMIFS('Sales Transactions'!$R$3:$R$82, 'Sales Transactions'!$O$3:$O$82, B63, 'Sales Transactions'!$L$3:$L$82, $G$4), IF($G$4="All Channels", SUMIFS('Sales Transactions'!$R$3:$R$82, 'Sales Transactions'!$O$3:$O$82, B63, 'Sales Transactions'!$H$3:$H$82, $C$4), SUMIFS('Sales Transactions'!$R$3:$R$82, 'Sales Transactions'!$O$3:$O$82, B63, 'Sales Transactions'!$H$3:$H$82, $C$4, 'Sales Transactions'!$L$3:$L$82, $G$4)))) -> 44 | D63: =IF(AND($C$4="All Basins", $G$4="All Channels"), SUMIFS('Sales Transactions'!$T$3:$T$82, 'Sales Transactions'!$O$3:$O$82, B63), IF($C$4="All Basins", SUMIFS('Sales Transactions'!$T$3:$T$82, 'Sales Transactions'!$O$3:$O$82, B63, 'Sales Transactions'!$L$3:$L$82, $G$4), IF($G$4="All Channels", SUMIFS('Sales Transactions'!$T$3:$T$82, 'Sales Transactions'!$O$3:$O$82, B63, 'Sales Transactions'!$H$3:$H$82, $C$4), SUMIFS('Sales Transactions'!$T$3:$T$82, 'Sales Transactions'!$O$3:$O$82, B63, 'Sales Transactions'!$H$3:$H$82, $C$4, 'Sales Transactions'!$L$3:$L$82, $G$4)))) -> 819000 | E63: =IF($D$67>0, D63/$D$67, 0) -> 0.2173 | F63: =IF(AND($C$4="All Basins", $G$4="All Channels"), SUMIFS('Sales Transactions'!$V$3:$V$82, 'Sales Transactions'!$O$3:$O$82, B63), IF($C$4="All Basins", SUMIFS('Sales Transactions'!$V$3:$V$82, 'Sales Transactions'!$O$3:$O$82, B63, 'Sales Transactions'!$L$3:$L$82, $G$4), IF($G$4="All Channels", SUMIFS('Sales Transactions'!$V$3:$V$82, 'Sales Transactions'!$O$3:$O$82, B63, 'Sales Transactions'!$H$3:$H$82, $C$4), SUMIFS('Sales Transactions'!$V$3:$V$82, 'Sales Transactions'!$O$3:$O$82, B63, 'Sales Transactions'!$H$3:$H$82, $C$4, 'Sales Transactions'!$L$3:$L$82, $G$4)))) -> 519800 | G63: =IF(D63>0, F63/D63, 0) -> 0.6347 | H63: =IF(D63>0, REPT("█", MIN(8, MAX(1, ROUND(D63/1427500*8, 0)))), "") -> █████ | I63: Spot Commodity Clearing | J63: =IF($K$66>0, K63/$K$66, 0) -> 0.267 | K63: =IF(AND($G$4<>"All Channels", $G$4<>I63), 0, IF($C$4="All Basins", SUMIFS('Sales Transactions'!$T$3:$T$82, 'Sales Transactions'!$L$3:$L$82, I63), SUMIFS('Sales Transactions'!$T$3:$T$82, 'Sales Transactions'!$L$3:$L$82, I63, 'Sales Transactions'!$H$3:$H$82, $C$4))) -> 1004910 | L63: =IF(AND($G$4<>"All Channels", $G$4<>I63), 0, IF($C$4="All Basins", SUMIFS('Sales Transactions'!$V$3:$V$82, 'Sales Transactions'!$L$3:$L$82, I63), SUMIFS('Sales Transactions'!$V$3:$V$82, 'Sales Transactions'!$L$3:$L$82, I63, 'Sales Transactions'!$H$3:$H$82, $C$4))) -> 652410 | M63: =IF(K63>0, L63/K63, 0) -> 0.64922232 | N63: Growing | O63: ■■■■
B64: Critical Minerals | C64: =IF(AND($C$4="All Basins", $G$4="All Channels"), SUMIFS('Sales Transactions'!$R$3:$R$82, 'Sales Transactions'!$O$3:$O$82, B64), IF($C$4="All Basins", SUMIFS('Sales Transactions'!$R$3:$R$82, 'Sales Transactions'!$O$3:$O$82, B64, 'Sales Transactions'!$L$3:$L$82, $G$4), IF($G$4="All Channels", SUMIFS('Sales Transactions'!$R$3:$R$82, 'Sales Transactions'!$O$3:$O$82, B64, 'Sales Transactions'!$H$3:$H$82, $C$4), SUMIFS('Sales Transactions'!$R$3:$R$82, 'Sales Transactions'!$O$3:$O$82, B64, 'Sales Transactions'!$H$3:$H$82, $C$4, 'Sales Transactions'!$L$3:$L$82, $G$4)))) -> 59 | D64: =IF(AND($C$4="All Basins", $G$4="All Channels"), SUMIFS('Sales Transactions'!$T$3:$T$82, 'Sales Transactions'!$O$3:$O$82, B64), IF($C$4="All Basins", SUMIFS('Sales Transactions'!$T$3:$T$82, 'Sales Transactions'!$O$3:$O$82, B64, 'Sales Transactions'!$L$3:$L$82, $G$4), IF($G$4="All Channels", SUMIFS('Sales Transactions'!$T$3:$T$82, 'Sales Transactions'!$O$3:$O$82, B64, 'Sales Transactions'!$H$3:$H$82, $C$4), SUMIFS('Sales Transactions'!$T$3:$T$82, 'Sales Transactions'!$O$3:$O$82, B64, 'Sales Transactions'!$H$3:$H$82, $C$4, 'Sales Transactions'!$L$3:$L$82, $G$4)))) -> 573825 | E64: =IF($D$67>0, D64/$D$67, 0) -> 0.1522 | F64: =IF(AND($C$4="All Basins", $G$4="All Channels"), SUMIFS('Sales Transactions'!$V$3:$V$82, 'Sales Transactions'!$O$3:$O$82, B64), IF($C$4="All Basins", SUMIFS('Sales Transactions'!$V$3:$V$82, 'Sales Transactions'!$O$3:$O$82, B64, 'Sales Transactions'!$L$3:$L$82, $G$4), IF($G$4="All Channels", SUMIFS('Sales Transactions'!$V$3:$V$82, 'Sales Transactions'!$O$3:$O$82, B64, 'Sales Transactions'!$H$3:$H$82, $C$4), SUMIFS('Sales Transactions'!$V$3:$V$82, 'Sales Transactions'!$O$3:$O$82, B64, 'Sales Transactions'!$H$3:$H$82, $C$4, 'Sales Transactions'!$L$3:$L$82, $G$4)))) -> 373225 | G64: =IF(D64>0, F64/D64, 0) -> 0.6504 | H64: =IF(D64>0, REPT("█", MIN(8, MAX(1, ROUND(D64/1427500*8, 0)))), "") -> ███ | I64: Long-Term Pipeline Offtake | J64: =IF($K$66>0, K64/$K$66, 0) -> 0.219 | K64: =IF(AND($G$4<>"All Channels", $G$4<>I64), 0, IF($C$4="All Basins", SUMIFS('Sales Transactions'!$T$3:$T$82, 'Sales Transactions'!$L$3:$L$82, I64), SUMIFS('Sales Transactions'!$T$3:$T$82, 'Sales Transactions'!$L$3:$L$82, I64, 'Sales Transactions'!$H$3:$H$82, $C$4))) -> 826730 | L64: =IF(AND($G$4<>"All Channels", $G$4<>I64), 0, IF($C$4="All Basins", SUMIFS('Sales Transactions'!$V$3:$V$82, 'Sales Transactions'!$L$3:$L$82, I64), SUMIFS('Sales Transactions'!$V$3:$V$82, 'Sales Transactions'!$L$3:$L$82, I64, 'Sales Transactions'!$H$3:$H$82, $C$4))) -> 514730 | M64: =IF(K64>0, L64/K64, 0) -> 0.62260956 | N64: Stable | O64: ■■■
B65: Exploration Geo | C65: =IF(AND($C$4="All Basins", $G$4="All Channels"), SUMIFS('Sales Transactions'!$R$3:$R$82, 'Sales Transactions'!$O$3:$O$82, B65), IF($C$4="All Basins", SUMIFS('Sales Transactions'!$R$3:$R$82, 'Sales Transactions'!$O$3:$O$82, B65, 'Sales Transactions'!$L$3:$L$82, $G$4), IF($G$4="All Channels", SUMIFS('Sales Transactions'!$R$3:$R$82, 'Sales Transactions'!$O$3:$O$82, B65, 'Sales Transactions'!$H$3:$H$82, $C$4), SUMIFS('Sales Transactions'!$R$3:$R$82, 'Sales Transactions'!$O$3:$O$82, B65, 'Sales Transactions'!$H$3:$H$82, $C$4, 'Sales Transactions'!$L$3:$L$82, $G$4)))) -> 36 | D65: =IF(AND($C$4="All Basins", $G$4="All Channels"), SUMIFS('Sales Transactions'!$T$3:$T$82, 'Sales Transactions'!$O$3:$O$82, B65), IF($C$4="All Basins", SUMIFS('Sales Transactions'!$T$3:$T$82, 'Sales Transactions'!$O$3:$O$82, B65, 'Sales Transactions'!$L$3:$L$82, $G$4), IF($G$4="All Channels", SUMIFS('Sales Transactions'!$T$3:$T$82, 'Sales Transactions'!$O$3:$O$82, B65, 'Sales Transactions'!$H$3:$H$82, $C$4), SUMIFS('Sales Transactions'!$T$3:$T$82, 'Sales Transactions'!$O$3:$O$82, B65, 'Sales Transactions'!$H$3:$H$82, $C$4, 'Sales Transactions'!$L$3:$L$82, $G$4)))) -> 552500 | E65: =IF($D$67>0, D65/$D$67, 0) -> 0.1466 | F65: =IF(AND($C$4="All Basins", $G$4="All Channels"), SUMIFS('Sales Transactions'!$V$3:$V$82, 'Sales Transactions'!$O$3:$O$82, B65), IF($C$4="All Basins", SUMIFS('Sales Transactions'!$V$3:$V$82, 'Sales Transactions'!$O$3:$O$82, B65, 'Sales Transactions'!$L$3:$L$82, $G$4), IF($G$4="All Channels", SUMIFS('Sales Transactions'!$V$3:$V$82, 'Sales Transactions'!$O$3:$O$82, B65, 'Sales Transactions'!$H$3:$H$82, $C$4), SUMIFS('Sales Transactions'!$V$3:$V$82, 'Sales Transactions'!$O$3:$O$82, B65, 'Sales Transactions'!$H$3:$H$82, $C$4, 'Sales Transactions'!$L$3:$L$82, $G$4)))) -> 354500 | G65: =IF(D65>0, F65/D65, 0) -> 0.6416 | H65: =IF(D65>0, REPT("█", MIN(8, MAX(1, ROUND(D65/1427500*8, 0)))), "") -> ███ | I65: Other Channels | J65: =IF($K$66>0, K65/$K$66, 0) -> 0.197 | K65: =IF(AND($G$4<>"All Channels", $G$4<>I65), 0, IF($C$4="All Basins", SUMIFS('Sales Transactions'!$T$3:$T$82, 'Sales Transactions'!$L$3:$L$82, I65), SUMIFS('Sales Transactions'!$T$3:$T$82, 'Sales Transactions'!$L$3:$L$82, I65, 'Sales Transactions'!$H$3:$H$82, $C$4))) -> 743285 | L65: =IF(AND($G$4<>"All Channels", $G$4<>I65), 0, IF($C$4="All Basins", SUMIFS('Sales Transactions'!$V$3:$V$82, 'Sales Transactions'!$L$3:$L$82, I65), SUMIFS('Sales Transactions'!$V$3:$V$82, 'Sales Transactions'!$L$3:$L$82, I65, 'Sales Transactions'!$H$3:$H$82, $C$4))) -> 474085 | M65: =IF(K65>0, L65/K65, 0) -> 0.63782398 | N65: Optimized | O65: ■■■
B66: Pipeline Transport | C66: =IF(AND($C$4="All Basins", $G$4="All Channels"), SUMIFS('Sales Transactions'!$R$3:$R$82, 'Sales Transactions'!$O$3:$O$82, B66), IF($C$4="All Basins", SUMIFS('Sales Transactions'!$R$3:$R$82, 'Sales Transactions'!$O$3:$O$82, B66, 'Sales Transactions'!$L$3:$L$82, $G$4), IF($G$4="All Channels", SUMIFS('Sales Transactions'!$R$3:$R$82, 'Sales Transactions'!$O$3:$O$82, B66, 'Sales Transactions'!$H$3:$H$82, $C$4), SUMIFS('Sales Transactions'!$R$3:$R$82, 'Sales Transactions'!$O$3:$O$82, B66, 'Sales Transactions'!$H$3:$H$82, $C$4, 'Sales Transactions'!$L$3:$L$82, $G$4)))) -> 35 | D66: =IF(AND($C$4="All Basins", $G$4="All Channels"), SUMIFS('Sales Transactions'!$T$3:$T$82, 'Sales Transactions'!$O$3:$O$82, B66), IF($C$4="All Basins", SUMIFS('Sales Transactions'!$T$3:$T$82, 'Sales Transactions'!$O$3:$O$82, B66, 'Sales Transactions'!$L$3:$L$82, $G$4), IF($G$4="All Channels", SUMIFS('Sales Transactions'!$T$3:$T$82, 'Sales Transactions'!$O$3:$O$82, B66, 'Sales Transactions'!$H$3:$H$82, $C$4), SUMIFS('Sales Transactions'!$T$3:$T$82, 'Sales Transactions'!$O$3:$O$82, B66, 'Sales Transactions'!$H$3:$H$82, $C$4, 'Sales Transactions'!$L$3:$L$82, $G$4)))) -> 231460 | E66: =IF($D$67>0, D66/$D$67, 0) -> 0.0614 | F66: =IF(AND($C$4="All Basins", $G$4="All Channels"), SUMIFS('Sales Transactions'!$V$3:$V$82, 'Sales Transactions'!$O$3:$O$82, B66), IF($C$4="All Basins", SUMIFS('Sales Transactions'!$V$3:$V$82, 'Sales Transactions'!$O$3:$O$82, B66, 'Sales Transactions'!$L$3:$L$82, $G$4), IF($G$4="All Channels", SUMIFS('Sales Transactions'!$V$3:$V$82, 'Sales Transactions'!$O$3:$O$82, B66, 'Sales Transactions'!$H$3:$H$82, $C$4), SUMIFS('Sales Transactions'!$V$3:$V$82, 'Sales Transactions'!$O$3:$O$82, B66, 'Sales Transactions'!$H$3:$H$82, $C$4, 'Sales Transactions'!$L$3:$L$82, $G$4)))) -> 150960 | G66: =IF(D66>0, F66/D66, 0) -> 0.6522 | H66: =IF(D66>0, REPT("█", MIN(8, MAX(1, ROUND(D66/1427500*8, 0)))), "") -> █ | I66: Total Channel Mix: | J66: 1 | K66: =SUM(K62:K65) -> 3769345 | L66: =SUM(L62:L65) -> 2392445 | M66: =IF(K66>0, L66/K66, 0) -> 0.6347
B67: Total Commodity Resource Type: | C67: =SUM(C62:C66) -> 240 | D67: =SUM(D62:D66) -> 3769345 | E67: 1 | F67: =SUM(F62:F66) -> 2392445 | G67: =IF(D67>0, F67/D67, 0) -> 0.6347 | H67: 100.0% | I67: ✓ 100% of Channel Revenue is dynamically validated against the Transaction Ledger
B69: NATURAL RESOURCES, OIL, GAS & MINING STRATEGIC INTELLIGENCE BRIEFING & C-SUITE MEMO
B70: 💡 Core Revenue Driver | E70: Top Category (Drilling Hardware) drives 37.9% of total revenue. | J70: Strong enterprise software adoption and expansion across strategic tier accounts have expanded gross margins to 63.5%.
B71: 🌍 Regional Performance | E71: Bakken Formation represents the strongest market theater with 106.4% quota attainment. | J71: Sales cycles averaged 42 days with strong partner ecosystem co-selling momentum in Tier-1 metropolitan markets.
B72: ⚖️ Margin Optimization | E72: Blended product margin stands at 63.5%, beating initial corporate budget targets by +2.8 bps. | J72: Discounting remained disciplined across Export LNG Terminal channels (averaging <7.5%), preserving net unit economics.
B73: 🛡️ Portfolio & Account Health | E73: 4 of 6 strategic accounts maintain an 'Optimal' health rating. | J73: Customer retention and multi-year contract renewals are paced to generate high recurring annual contract value (ACV).
B75: CONFIDENTIAL • Built in native Microsoft Excel (.xlsx) format with real interactive DrawingML charts and live formulas • Compatible with Microsoft 365, Google Sheets, & Apple Numbers
B78: 📊 DATTA SABLE — EXECUTIVE BI DASHBOARDS & FINANCIAL MODELING PORTFOLIO
B79: 🔗 Click here or click the portfolio preview image below to visit https://dattasable.com/dashboards
B113: Executive Analytics Portfolio • Datta Sable • Direct Link: https://dattasable.com/dashboards

Sheet Pivot Table Analysis
B2: OIL_GAS_MINING INC — NATURAL RESOURCES, OIL, GAS & MINING PIVOT ANALYSIS & MATRIX
B3: Dynamic Aggregate Pivot Engine • Interactive Formulas • Multi-Dimensional Matrix Calculations with Native Visual Pivot Charts
B4: Basin / Concession Area: | C4: All Basins | E4: Channel: | F4: All Channels | H4: 💡 Tip: Select C4 (Basin / Concession Area) or F4 (Channel) to filter all Pivot Tables & adjacent Pivot Charts dynamically!
B5: PIVOT TABLE 1: BASIN / CONCESSION AREA BY CHANNEL CROSS-TABULATION MATRIX
B6: Basin / Concession Area | C6: Export LNG Terminal | D6: Spot Commodity Clearing | E6: Long-Term Pipeline Offtake | F6: Other Channels | G6: Total Upstream Production Revenue | H6: Total Net Crack Spread & Refining Margin | I6: Blended Margin
B7: Bakken Formation | C7: =IF(AND($C$4<>"All Basins", $C$4<>$B7), 0, IF(AND($F$4<>"All Channels", $F$4<>"Export LNG Terminal"), 0, SUMIFS('Sales Transactions'!$T$3:$T$82, 'Sales Transactions'!$H$3:$H$82, $B7, 'Sales Transactions'!$L$3:$L$82, "Export LNG Terminal"))) -> 186095 | D7: =IF(AND($C$4<>"All Basins", $C$4<>$B7), 0, IF(AND($F$4<>"All Channels", $F$4<>"Spot Commodity Clearing"), 0, SUMIFS('Sales Transactions'!$T$3:$T$82, 'Sales Transactions'!$H$3:$H$82, $B7, 'Sales Transactions'!$L$3:$L$82, "Spot Commodity Clearing"))) -> 375970 | E7: =IF(AND($C$4<>"All Basins", $C$4<>$B7), 0, IF(AND($F$4<>"All Channels", $F$4<>"Long-Term Pipeline Offtake"), 0, SUMIFS('Sales Transactions'!$T$3:$T$82, 'Sales Transactions'!$H$3:$H$82, $B7, 'Sales Transactions'!$L$3:$L$82, "Long-Term Pipeline Offtake"))) -> 112840 | F7: =IF(AND($C$4<>"All Basins", $C$4<>$B7), 0, IF($F$4<>"All Channels", IF(OR($F$4="Export LNG Terminal", $F$4="Spot Commodity Clearing", $F$4="Long-Term Pipeline Offtake"), 0, SUMIFS('Sales Transactions'!$T$3:$T$82, 'Sales Transactions'!$H$3:$H$82, $B7, 'Sales Transactions'!$L$3:$L$82, $F$4)), MAX(0, SUMIFS('Sales Transactions'!$T$3:$T$82, 'Sales Transactions'!$H$3:$H$82, $B7) - SUM($C7:$E7)))) -> 194925 | G7: =SUM(C7:F7) -> 869830 | H7: =IF(AND($C$4<>"All Basins", $C$4<>$B7), 0, IF($F$4="All Channels", SUMIFS('Sales Transactions'!$V$3:$V$82, 'Sales Transactions'!$H$3:$H$82, $B7), SUMIFS('Sales Transactions'!$V$3:$V$82, 'Sales Transactions'!$H$3:$H$82, $B7, 'Sales Transactions'!$L$3:$L$82, $F$4))) -> 562330 | I7: =IF(G7>0, H7/G7, 0) -> 0.6465
B8: Permian Delaware Basin | C8: =IF(AND($C$4<>"All Basins", $C$4<>$B8), 0, IF(AND($F$4<>"All Channels", $F$4<>"Export LNG Terminal"), 0, SUMIFS('Sales Transactions'!$T$3:$T$82, 'Sales Transactions'!$H$3:$H$82, $B8, 'Sales Transactions'!$L$3:$L$82, "Export LNG Terminal"))) -> 629100 | D8: =IF(AND($C$4<>"All Basins", $C$4<>$B8), 0, IF(AND($F$4<>"All Channels", $F$4<>"Spot Commodity Clearing"), 0, SUMIFS('Sales Transactions'!$T$3:$T$82, 'Sales Transactions'!$H$3:$H$82, $B8, 'Sales Transactions'!$L$3:$L$82, "Spot Commodity Clearing"))) -> 213595 | E8: =IF(AND($C$4<>"All Basins", $C$4<>$B8), 0, IF(AND($F$4<>"All Channels", $F$4<>"Long-Term Pipeline Offtake"), 0, SUMIFS('Sales Transactions'!$T$3:$T$82, 'Sales Transactions'!$H$3:$H$82, $B8, 'Sales Transactions'!$L$3:$L$82, "Long-Term Pipeline Offtake"))) -> 77950 | F8: =IF(AND($C$4<>"All Basins", $C$4<>$B8), 0, IF($F$4<>"All Channels", IF(OR($F$4="Export LNG Terminal", $F$4="Spot Commodity Clearing", $F$4="Long-Term Pipeline Offtake"), 0, SUMIFS('Sales Transactions'!$T$3:$T$82, 'Sales Transactions'!$H$3:$H$82, $B8, 'Sales Transactions'!$L$3:$L$82, $F$4)), MAX(0, SUMIFS('Sales Transactions'!$T$3:$T$82, 'Sales Transactions'!$H$3:$H$82, $B8) - SUM($C8:$E8)))) -> 136600 | G8: =SUM(C8:F8) -> 1057245 | H8: =IF(AND($C$4<>"All Basins", $C$4<>$B8), 0, IF($F$4="All Channels", SUMIFS('Sales Transactions'!$V$3:$V$82, 'Sales Transactions'!$H$3:$H$82, $B8), SUMIFS('Sales Transactions'!$V$3:$V$82, 'Sales Transactions'!$H$3:$H$82, $B8, 'Sales Transactions'!$L$3:$L$82, $F$4))) -> 670145 | I8: =IF(G8>0, H8/G8, 0) -> 0.6339
B9: Athabasca Resource Zone | C9: =IF(AND($C$4<>"All Basins", $C$4<>$B9), 0, IF(AND($F$4<>"All Channels", $F$4<>"Export LNG Terminal"), 0, SUMIFS('Sales Transactions'!$T$3:$T$82, 'Sales Transactions'!$H$3:$H$82, $B9, 'Sales Transactions'!$L$3:$L$82, "Export LNG Terminal"))) -> 59850 | D9: =IF(AND($C$4<>"All Basins", $C$4<>$B9), 0, IF(AND($F$4<>"All Channels", $F$4<>"Spot Commodity Clearing"), 0, SUMIFS('Sales Transactions'!$T$3:$T$82, 'Sales Transactions'!$H$3:$H$82, $B9, 'Sales Transactions'!$L$3:$L$82, "Spot Commodity Clearing"))) -> 321895 | E9: =IF(AND($C$4<>"All Basins", $C$4<>$B9), 0, IF(AND($F$4<>"All Channels", $F$4<>"Long-Term Pipeline Offtake"), 0, SUMIFS('Sales Transactions'!$T$3:$T$82, 'Sales Transactions'!$H$3:$H$82, $B9, 'Sales Transactions'!$L$3:$L$82, "Long-Term Pipeline Offtake"))) -> 297890 | F9: =IF(AND($C$4<>"All Basins", $C$4<>$B9), 0, IF($F$4<>"All Channels", IF(OR($F$4="Export LNG Terminal", $F$4="Spot Commodity Clearing", $F$4="Long-Term Pipeline Offtake"), 0, SUMIFS('Sales Transactions'!$T$3:$T$82, 'Sales Transactions'!$H$3:$H$82, $B9, 'Sales Transactions'!$L$3:$L$82, $F$4)), MAX(0, SUMIFS('Sales Transactions'!$T$3:$T$82, 'Sales Transactions'!$H$3:$H$82, $B9) - SUM($C9:$E9)))) -> 169640 | G9: =SUM(C9:F9) -> 849275 | H9: =IF(AND($C$4<>"All Basins", $C$4<>$B9), 0, IF($F$4="All Channels", SUMIFS('Sales Transactions'!$V$3:$V$82, 'Sales Transactions'!$H$3:$H$82, $B9), SUMIFS('Sales Transactions'!$V$3:$V$82, 'Sales Transactions'!$H$3:$H$82, $B9, 'Sales Transactions'!$L$3:$L$82, $F$4))) -> 544975 | I9: =IF(G9>0, H9/G9, 0) -> 0.6417
B10: Eagle Ford Shale Play | C10: =IF(AND($C$4<>"All Basins", $C$4<>$B10), 0, IF(AND($F$4<>"All Channels", $F$4<>"Export LNG Terminal"), 0, SUMIFS('Sales Transactions'!$T$3:$T$82, 'Sales Transactions'!$H$3:$H$82, $B10, 'Sales Transactions'!$L$3:$L$82, "Export LNG Terminal"))) -> 226025 | D10: =IF(AND($C$4<>"All Basins", $C$4<>$B10), 0, IF(AND($F$4<>"All Channels", $F$4<>"Spot Commodity Clearing"), 0, SUMIFS('Sales Transactions'!$T$3:$T$82, 'Sales Transactions'!$H$3:$H$82, $B10, 'Sales Transactions'!$L$3:$L$82, "Spot Commodity Clearing"))) -> 19950 | E10: =IF(AND($C$4<>"All Basins", $C$4<>$B10), 0, IF(AND($F$4<>"All Channels", $F$4<>"Long-Term Pipeline Offtake"), 0, SUMIFS('Sales Transactions'!$T$3:$T$82, 'Sales Transactions'!$H$3:$H$82, $B10, 'Sales Transactions'!$L$3:$L$82, "Long-Term Pipeline Offtake"))) -> 321250 | F10: =IF(AND($C$4<>"All Basins", $C$4<>$B10), 0, IF($F$4<>"All Channels", IF(OR($F$4="Export LNG Terminal", $F$4="Spot Commodity Clearing", $F$4="Long-Term Pipeline Offtake"), 0, SUMIFS('Sales Transactions'!$T$3:$T$82, 'Sales Transactions'!$H$3:$H$82, $B10, 'Sales Transactions'!$L$3:$L$82, $F$4)), MAX(0, SUMIFS('Sales Transactions'!$T$3:$T$82, 'Sales Transactions'!$H$3:$H$82, $B10) - SUM($C10:$E10)))) -> 177450 | G10: =SUM(C10:F10) -> 744675 | H10: =IF(AND($C$4<>"All Basins", $C$4<>$B10), 0, IF($F$4="All Channels", SUMIFS('Sales Transactions'!$V$3:$V$82, 'Sales Transactions'!$H$3:$H$82, $B10), SUMIFS('Sales Transactions'!$V$3:$V$82, 'Sales Transactions'!$H$3:$H$82, $B10, 'Sales Transactions'!$L$3:$L$82, $F$4))) -> 456575 | I10: =IF(G10>0, H10/G10, 0) -> 0.6131
B11: Total Basin / Concession Area Upstream Production Revenue: | C11: =SUM(C7:C10) -> 1194420 | D11: =SUM(D7:D10) -> 1004910 | E11: =SUM(E7:E10) -> 826730 | F11: =SUM(F7:F10) -> 743285 | G11: =SUM(G7:G10) -> 3769345 | H11: =SUM(H7:H10) -> 2392445 | I11: =IF(G11>0, H11/G11, 0) -> 0.6347
B13: PIVOT TABLE 2: COMMODITY RESOURCE TYPE PORTFOLIO BY BASIN / CONCESSION AREA
B14: Commodity Resource Type | C14: Bakken Formation | D14: Permian Delaware Basin | E14: Athabasca Resource Zone | F14: Eagle Ford Shale Play | G14: Total Upstream Production Revenue | H14: Total Active Rig Fields / Mineral Leases | I14: Extraction Safety Adherence %
